<?xml version="1.0"?>
<!-- Revolute-Revolute Manipulator -->
<robot name="orange" xmlns:xacro="http://www.ros.org/wiki/xacro">

  <!-- Constants for robot dimensions -->
  <xacro:property name="PI" value="3.1415926535897931"/>
  
  <!-- Macro -->
  <xacro:macro name="box_inertia" params="m x y z">
    <inertia ixx="${m*(y*y+z*z)/12.0}" ixy = "0.0" ixz = "0.0"
             iyy="${m*(z*z+x*x)/12.0}" iyz = "0.0"
             izz="${m*(x*x+y*y)/12.0}" />
  </xacro:macro>
  <xacro:macro name="cylinder_inertia" params="m r h">
    <inertia ixx="${m*(3*r*r+h*h)/12.0}" ixy = "0.0" ixz = "0.0"
             iyy="${m*(3*r*r+h*h)/12.0}" iyz = "0.0"
             izz="${m*r*r/2.0}" />
  </xacro:macro>

  <!-- Import gazebo reference -->
  <xacro:include filename="$(find igvc2023)/urdf/orange.gazebo"/>
  
  <!-- Import 2D LiDAR model -->
  <xacro:include filename="$(find igvc2023)/urdf/sensors/hokuyo.urdf.xacro"/>
  <xacro:sensor_hokuyo name="hokuyo" parent="base_link" min_angle="-1.22" max_angle="1.22" samples="720">
    <origin xyz="0.16 0.0 0.05" rpy="0.0 0.0 0.0"/>
  </xacro:sensor_hokuyo>
  
  <!-- Import 3D LiDAR model -->
  <xacro:include filename="$(find igvc2023)/urdf/sensors/velodyne.urdf.xacro"/>
  <xacro:sensor_velodyne name="velodyne" parent="base_link" min_angle="-2.35619" max_angle="2.35619" samples="720">
    <origin xyz="-0.13 0.0 0.70" rpy="0.0 0.0 0.0"/>
  </xacro:sensor_velodyne>
  
  <!-- Import imu model -->
  <xacro:include filename="$(find igvc2023)/urdf/sensors/imu.urdf.xacro"/>
  <xacro:sensor_imu name="imu" parent="base_link" size="0.05 0.05 0.05">
    <origin xyz="0 0.0 0.068" rpy="0.0 0.0 0.0"/>
  </xacro:sensor_imu>
  
  <!-- Import fisheye camera model -->
  <xacro:include filename="$(find igvc2023)/urdf/sensors/camera.urdf.xacro"/>
  <xacro:sensor_camera name="camera" parent="base_link">
    <origin xyz="-0.13 0 1" rpy="0 0 0"/>
  </xacro:sensor_camera>
  
  <!-- Import gps model -->
  <xacro:include filename="$(find igvc2023)/urdf/sensors/gps.urdf.xacro"/>
  <xacro:sensor_gps name="gps" parent="base_link">
    <origin xyz="0.5 0 0.75" rpy="0 ${PI} 0"/>
  </xacro:sensor_gps>
  
  <!-- Base Footprint -->
  <joint name="base_joint" type="fixed">
    <parent link="base_footprint"/>
    <child link="base_link"/>
    <origin xyz="0.0 0.0 0.1015" rpy="0 0 0"/>
  </joint>
  
  <link name="base_footprint"/>
  
  <!-- Base Link -->
  <link name="base_link">
    <collision>
      <origin xyz="-0.33 0.0 0.25" rpy="0.0 0.0 0.0"/>
      <geometry>
        <box size="0.9 0.5 0.5"/>
      </geometry>
    </collision>

    <visual>
      <origin xyz="-0.355 0.0 0.3" rpy="0.0 0.0 0.0"/>
      <geometry>
        <mesh filename="package://igvc2023/meshes/IGVCchassis.dae"/>
      </geometry>
    </visual>

    <inertial>
       <mass value="40" />
       <origin xyz="-0.33 0.0 0.26" rpy="0.0 0.0 0.0"/>
       <xacro:box_inertia m="40" x="0.9" y="0.5" z="0.45"/>
    </inertial>
  </link>
  
  <!-- Back wheels -->
  <joint name="left_caster_hinge" type ="fixed">
    <origin xyz="0.0 0.0 0.0" rpy="0.0 0.0 0.0"/>
    <child link="left_caster_link"/>
    <parent link="base_link"/>
  </joint>
  
  <joint name="right_caster_hinge" type ="fixed">
    <origin xyz="0.0 0.0 0.0" rpy="0.0 0.0 0.0"/>
    <child link="right_caster_link"/>
    <parent link="base_link"/>
  </joint>
  
  <link name="left_caster_link">
    <collision>
      <origin xyz="-0.735 0.10 -0.039" rpy="0.0 ${PI/2} ${PI/2}"/>
      <geometry>
        <sphere radius="0.0625"/>
      </geometry>
    </collision>
    
    <visual>
      <origin xyz="-0.735 0.10 -0.039" rpy="0.0 0.0 0.0"/>
      <geometry>
        <mesh filename="package://igvc2023/meshes/left_back_wheel.dae"/>
      </geometry>
    </visual>
  </link>
  
  <link name="right_caster_link">
    <collision>
      <origin xyz="-0.735 -0.10 -0.039" rpy="0.0 ${PI/2} ${PI/2}"/>
      <geometry>
        <sphere radius="0.0625"/>
      </geometry>
    </collision>
    
    <visual>
      <origin xyz="-0.735 -0.10 -0.039" rpy="0.0 0.0 0.0"/>
      <geometry>
        <mesh filename="package://igvc2023/meshes/right_back_wheel.dae"/>
        <sphere radius="0.0625"/>
      </geometry>
    </visual>
  </link>
  
  <!-- Front wheels -->
  <joint type="revolute" name="left_wheel_hinge">
    <origin xyz="0.0 0.28 0.0" rpy="0.0 0.0 0.0"/>
    <child link="left_wheel">left_wheel</child>
    <parent link="base_link">base_link</parent>
    <axis xyz="0 1 0"/>
    <limit effort="100" velocity="100.0"  lower="-5000" upper="5000" />
  </joint>
  
  <joint type="revolute" name="right_wheel_hinge">
    <origin xyz="0.0 -0.28 0.0" rpy="0.0 0.0 0.0"/>
    <child link="right_wheel">right_wheel</child>
    <parent link="base_link">base_link</parent>
    <axis xyz="0 1 0"/>
    <limit effort="100" velocity="100.0"  lower="-5000" upper="5000" />
  </joint>
  
  <link name="left_wheel">
    <collision name="collision">
      <origin xyz="0.0 0.0 0.0" rpy="0.0 ${PI/2} ${PI/2}"/>
      <geometry>
        <cylinder length="0.047" radius="0.1015"/>
      </geometry>
    </collision>
    
    <visual name="visual">
      <origin xyz="0.0 0.0 0.0" rpy="0.0 0.0 0.0"/>
      <geometry>
        <mesh filename="package://igvc2023/meshes/front_wheel.dae"/>
      </geometry>
    </visual>
    
    <inertial>
       <mass value="3.4" />
       <origin xyz="0.0 0.0 0.0" rpy="0.0 ${PI/2} ${PI/2}"/>
       <xacro:cylinder_inertia m="3.4" r="0.1015" h="0.047"/>
    </inertial>
  </link>
  
  <link name="right_wheel">
    <collision name="collision">
      <origin xyz="0.0 0.0 0.0" rpy="0.0 ${PI/2} ${PI/2}"/>
      <geometry>
        <cylinder length="0.047" radius="0.1015"/>
      </geometry>
    </collision>
    
    <visual name="visual">
      <origin xyz="0.0 0.0 0.0" rpy="0.0 0.0 0.0"/>
      <geometry>
        <mesh filename="package://igvc2023/meshes/front_wheel.dae"/>
      </geometry>
    </visual>
    
    <inertial>
       <mass value="3.4" />
       <origin xyz="0.0 0.0 0.0" rpy="0.0 ${PI/2} ${PI/2}"/>
       <xacro:cylinder_inertia m="3.4" r="0.1015" h="0.047"/>
    </inertial>
  </link>
</robot>
